<?xml version="1.0" encoding="utf-8"?>
<!-- This URDF was automatically created by SolidWorks to URDF Exporter! Originally created by Stephen Brawner (brawner@gmail.com) 
     Commit Version: 1.6.0-1-g15f4949  Build Version: 1.6.7594.29634
     For more information, please see http://wiki.ros.org/sw_urdf_exporter -->
<robot
  name="efectorfinal">
  <link
    name="base_link">
    <inertial>
      <origin
        xyz="3.4843E-19 0.0024516 0.051521"
        rpy="0 0 0" />
      <mass
        value="0.16854" />
      <inertia
        ixx="0.0001602"
        ixy="1.3986E-21"
        ixz="1.375E-21"
        iyy="0.00015752"
        iyz="-2.4381E-06"
        izz="4.6113E-05" />
    </inertial>
    <visual>
      <origin
        xyz="0 0 0"
        rpy="0 0 0" />
      <geometry>
        <mesh
          filename="package://efectorfinal/meshes/base_link.STL" />
      </geometry>
      <material
        name="">
        <color
          rgba="0.79216 0.81961 0.93333 1" />
      </material>
    </visual>
    <collision>
      <origin
        xyz="0 0 0"
        rpy="0 0 0" />
      <geometry>
        <mesh
          filename="package://efectorfinal/meshes/base_link.STL" />
      </geometry>
    </collision>
  </link>
  <link
    name="first_link">
    <inertial>
      <origin
        xyz="0.026879 0.0068778 0.0033069"
        rpy="0 0 0" />
      <mass
        value="0.010354" />
      <inertia
        ixx="1.6581E-06"
        ixy="4.7347E-08"
        ixz="2.3376E-07"
        iyy="2.8867E-06"
        iyz="-4.2874E-07"
        izz="2.8973E-06" />
    </inertial>
    <visual>
      <origin
        xyz="0 0 0"
        rpy="0 0 0" />
      <geometry>
        <mesh
          filename="package://efectorfinal/meshes/first_link.STL" />
      </geometry>
      <material
        name="">
        <color
          rgba="0.64314 0.61569 0.6 1" />
      </material>
    </visual>
    <collision>
      <origin
        xyz="0 0 0"
        rpy="0 0 0" />
      <geometry>
        <mesh
          filename="package://efectorfinal/meshes/first_link.STL" />
      </geometry>
    </collision>
  </link>
  <joint
    name="first_joint"
    type="prismatic">
    <origin
      xyz="-0.03 0.058 0.099"
      rpy="-1.5708 0 0" />
    <parent
      link="base_link" />
    <child
      link="first_link" />
    <axis
      xyz="0 0 0" />
    <limit
      lower="-0.02"
      upper="0.02"
      effort="0"
      velocity="0" />
  </joint>
  <link
    name="second_link">
    <inertial>
      <origin
        xyz="0.026879 0.0068778 0.0033069"
        rpy="0 0 0" />
      <mass
        value="0.010354" />
      <inertia
        ixx="1.6581E-06"
        ixy="4.7347E-08"
        ixz="2.3376E-07"
        iyy="2.8867E-06"
        iyz="-4.2874E-07"
        izz="2.8973E-06" />
    </inertial>
    <visual>
      <origin
        xyz="0 0 0"
        rpy="0 0 0" />
      <geometry>
        <mesh
          filename="package://efectorfinal/meshes/second_link.STL" />
      </geometry>
      <material
        name="">
        <color
          rgba="0.64314 0.61569 0.6 1" />
      </material>
    </visual>
    <collision>
      <origin
        xyz="0 0 0"
        rpy="0 0 0" />
      <geometry>
        <mesh
          filename="package://efectorfinal/meshes/second_link.STL" />
      </geometry>
    </collision>
  </link>
  <joint
    name="second_joint"
    type="prismatic">
    <origin
      xyz="0.03 0.058 0.061"
      rpy="1.5708 0 -3.1416" />
    <parent
      link="base_link" />
    <child
      link="second_link" />
    <axis
      xyz="0 0 0" />
    <limit
      lower="-0.02"
      upper="0.02"
      effort="0"
      velocity="0" />
  </joint>
</robot>