<?xml version="1.0" encoding="utf-8"?>
<!-- This URDF was automatically created by SolidWorks to URDF Exporter! Originally created by Stephen Brawner (brawner@gmail.com) 
     Commit Version: 1.6.0-1-g15f4949  Build Version: 1.6.7594.29634
     For more information, please see http://wiki.ros.org/sw_urdf_exporter -->
<robot
  name="efectorfinal">
  <link
    name="base_link">
    <inertial>
      <origin
        xyz="-2.20198089757877E-17 0.0474920624530793 0.0295646249597823"
        rpy="0 0 0" />
      <mass
        value="0.162356194490192" />
      <inertia
        ixx="0.000159792357924796"
        ixy="1.85863485064781E-22"
        ixz="-3.12354534970082E-22"
        iyy="0.000156785919290839"
        iyz="-2.43810022521945E-06"
        izz="4.57025577317508E-05" />
    </inertial>
    <visual>
      <origin
        xyz="0 0 0"
        rpy="0 0 0" />
      <geometry>
        <mesh
          filename="package://efectorfinal/meshes/base_link.STL" />
      </geometry>
      <material
        name="">
        <color
          rgba="0.792156862745098 0.819607843137255 0.933333333333333 1" />
      </material>
    </visual>
    <collision>
      <origin
        xyz="0 0 0"
        rpy="0 0 0" />
      <geometry>
        <mesh
          filename="package://efectorfinal/meshes/base_link.STL" />
      </geometry>
    </collision>
  </link>
  <link
    name="first_Link">
    <inertial>
      <origin
        xyz="0.00544675809815641 -5.79206069234475E-18 -1.67153584412282E-18"
        rpy="0 0 0" />
      <mass
        value="0.00618813972610106" />
      <inertia
        ixx="7.31511462021311E-07"
        ixy="-5.1966016748925E-23"
        ixz="-8.25763220740865E-23"
        iyy="4.10659781832087E-07"
        iyz="-1.22422730657848E-22"
        izz="4.10659781832087E-07" />
    </inertial>
    <visual>
      <origin
        xyz="0 0 0"
        rpy="0 0 0" />
      <geometry>
        <mesh
          filename="package://efectorfinal/meshes/first_Link.STL" />
      </geometry>
      <material
        name="">
        <color
          rgba="0.643137254901961 0.615686274509804 0.6 1" />
      </material>
    </visual>
    <collision>
      <origin
        xyz="0 0 0"
        rpy="0 0 0" />
      <geometry>
        <mesh
          filename="package://efectorfinal/meshes/first_Link.STL" />
      </geometry>
    </collision>
  </link>
  <joint
    name="first_joint"
    type="revolute">
    <origin
      xyz="0 0 0"
      rpy="1.7003 0 -1.5708" />
    <parent
      link="base_link" />
    <child
      link="first_Link" />
    <axis
      xyz="-1 0 0" />
    <limit
      lower="0"
      upper="0"
      effort="0"
      velocity="0" />
  </joint>
  <link
    name="second_link">
    <inertial>
      <origin
        xyz="0.0265211929009696 0.0068777834733057 0.00330694539119235"
        rpy="0 0 0" />
      <mass
        value="0.0103535967073896" />
      <inertia
        ixx="1.6581225771421E-06"
        ixy="4.73469728497251E-08"
        ixz="2.33763865274835E-07"
        iyy="2.88673763683143E-06"
        iyz="-4.28743016977691E-07"
        izz="2.89730942578623E-06" />
    </inertial>
    <visual>
      <origin
        xyz="0 0 0"
        rpy="0 0 0" />
      <geometry>
        <mesh
          filename="package://efectorfinal/meshes/second_link.STL" />
      </geometry>
      <material
        name="">
        <color
          rgba="0.643137254901961 0.615686274509804 0.6 1" />
      </material>
    </visual>
    <collision>
      <origin
        xyz="0 0 0"
        rpy="0 0 0" />
      <geometry>
        <mesh
          filename="package://efectorfinal/meshes/second_link.STL" />
      </geometry>
    </collision>
  </link>
  <joint
    name="second_joint"
    type="continuous">
    <origin
      xyz="0.01 -0.0148310357596693 0.0332408501719503"
      rpy="-1.5707963267949 1.44128079438183 -1.5707963267949" />
    <parent
      link="first_Link" />
    <child
      link="second_link" />
    <axis
      xyz="1 0 0" />
  </joint>
  <link
    name="third_link">
    <inertial>
      <origin
        xyz="0.0265211929010353 0.00687778347389024 0.0033069453916871"
        rpy="0 0 0" />
      <mass
        value="0.0103535967081163" />
      <inertia
        ixx="1.65812257734969E-06"
        ixy="4.73469728057163E-08"
        ixz="2.33763865266828E-07"
        iyy="2.88673763690313E-06"
        iyz="-4.28743017010508E-07"
        izz="2.89730942595185E-06" />
    </inertial>
    <visual>
      <origin
        xyz="0 0 0"
        rpy="0 0 0" />
      <geometry>
        <mesh
          filename="package://efectorfinal/meshes/third_link.STL" />
      </geometry>
      <material
        name="">
        <color
          rgba="0.643137254901961 0.615686274509804 0.6 1" />
      </material>
    </visual>
    <collision>
      <origin
        xyz="0 0 0"
        rpy="0 0 0" />
      <geometry>
        <mesh
          filename="package://efectorfinal/meshes/third_link.STL" />
      </geometry>
    </collision>
  </link>
  <joint
    name="third_joint"
    type="continuous">
    <origin
      xyz="0.01 0.0148375966439305 -0.0331904766116383"
      rpy="1.5707963267949 -1.44128079438183 1.5707963267949" />
    <parent
      link="first_Link" />
    <child
      link="third_link" />
    <axis
      xyz="1 0 0" />
  </joint>
</robot>